<?xml version="1.0" ?>
<!-- =================================================================================== -->
<!-- |    This document was autogenerated by xacro from mobile_manipulator.xacro       | -->
<!-- |    EDITING THIS FILE BY HAND IS NOT RECOMMENDED                                 | -->
<!-- =================================================================================== -->
<robot name="mobile_manipulator">
  <!-- Gazebo references -->
  <gazebo reference="base_link">
    <mu1 value="0.1"/>
    <mu2 value="0.1"/>
    <!-- <kp  value="10000000.0" />
  <kd  value="1.0" /> -->
    <material>Gazebo/White</material>
  </gazebo>
  <gazebo reference="front_left_steering_link">
    <!-- <selfCollide>false</selfCollide> -->
    <mu1 value="0.5"/>
    <mu2 value="0.5"/>
    <material>Gazebo/Grey</material>
  </gazebo>
  <gazebo reference="front_right_steering_link">
    <!-- <selfCollide>false</selfCollide> -->
    <mu1 value="0.5"/>
    <mu2 value="0.5"/>
    <material>Gazebo/Grey</material>
  </gazebo>
  <gazebo reference="rear_left_steering_link">
    <!-- <selfCollide>false</selfCollide> -->
    <mu1 value="1.5"/>
    <mu2 value="1.5"/>
    <material>Gazebo/Grey</material>
  </gazebo>
  <gazebo reference="rear_right_steering_link">
    <!-- <selfCollide>false</selfCollide> -->
    <mu1 value="1.5"/>
    <mu2 value="1.5"/>
    <material>Gazebo/Grey</material>
  </gazebo>
  <gazebo reference="ffl_wheel_link">
    <!-- <selfCollide>false</selfCollide> -->
    <mu1>0.8</mu1>
    <mu2>0.8</mu2>
    <kp>10000000.0</kp>
    <kd>1.0</kd>
    <minDepth>0.001</minDepth>
    <maxVel>0.1</maxVel>
    <fdir1>1 0 0</fdir1>
    <material>Gazebo/Grey</material>
  </gazebo>
  <gazebo reference="ffr_wheel_link">
    <!-- <selfCollide>false</selfCollide> -->
    <mu1>0.8</mu1>
    <mu2>0.8</mu2>
    <kp>10000000.0</kp>
    <kd>1.0</kd>
    <minDepth>0.001</minDepth>
    <maxVel>0.1</maxVel>
    <fdir1>1 0 0</fdir1>
    <material>Gazebo/Grey</material>
  </gazebo>
  <gazebo reference="rfl_wheel_link">
    <!-- <selfCollide>false</selfCollide> -->
    <mu1>0.8</mu1>
    <mu2>0.8</mu2>
    <kp>10000000.0</kp>
    <kd>1.0</kd>
    <minDepth>0.001</minDepth>
    <maxVel>0.1</maxVel>
    <fdir1>1 0 0</fdir1>
    <material>Gazebo/Grey</material>
  </gazebo>
  <gazebo reference="rfr_wheel_link">
    <!-- <selfCollide>false</selfCollide> -->
    <mu1>0.8</mu1>
    <mu2>0.8</mu2>
    <kp>10000000.0</kp>
    <kd>1.0</kd>
    <minDepth>0.001</minDepth>
    <maxVel>0.1</maxVel>
    <fdir1>1 0 0</fdir1>
    <material>Gazebo/Grey</material>
  </gazebo>
  <link name="base_link">
    <inertial>
      <origin rpy="0 0 0" xyz="0.0562591525803034 5.21904025701792E-05 0.108402855968814"/>
      <mass value="17.8446713847014"/>
      <inertia ixx="0.114563750887795" ixy="1.00505607229726E-06" ixz="-0.00308015585160256" iyy="0.25640701981465" iyz="-1.26769813175445E-06" izz="0.33939943437936"/>
    </inertial>
    <visual>
      <origin rpy="0 0 0" xyz="0 0 0"/>
      <geometry>
        <mesh filename="package://ranger_mini/meshes/base_link.STL"/>
      </geometry>
      <material name="">
        <color rgba="0.792156862745098 0.819607843137255 0.933333333333333 1"/>
      </material>
    </visual>
    <collision>
      <origin rpy="0 0 0" xyz="0 0 0"/>
      <geometry>
        <mesh filename="package://ranger_mini/meshes/base_link.STL"/>
      </geometry>
    </collision>
  </link>
  <link name="front_left_steering_link">
    <inertial>
      <origin rpy="0 0 0" xyz="-0.0078125 1.2678E-05 0.060941"/>
      <mass value="0.30421"/>
      <inertia ixx="0.00022406" ixy="-5.3036E-09" ixz="-1.2289E-08" iyy="0.00021285" iyz="-2.5969E-08" izz="0.00027948"/>
    </inertial>
    <visual>
      <origin rpy="0 0 0" xyz="0 0 0"/>
      <geometry>
        <mesh filename="package://ranger_mini/meshes/front_left_steering_link.STL"/>
      </geometry>
      <material name="">
        <color rgba="0.79216 0.81961 0.93333 1"/>
      </material>
    </visual>
    <collision>
      <origin rpy="0 0 0" xyz="0 0 0"/>
      <geometry>
        <mesh filename="package://ranger_mini/meshes/front_left_steering_link.STL"/>
      </geometry>
    </collision>
  </link>
  <joint name="front_left_steering_joint" type="revolute">
    <origin rpy="3.1416 0 1.5708" xyz="0.26366 0.18001 0.0557"/>
    <parent link="base_link"/>
    <child link="front_left_steering_link"/>
    <axis xyz="0 0 1"/>
    <limit effort="5" lower="-2.1" upper="2.1" velocity="6.28"/>
  </joint>
  <link name="ffl_wheel_link">
    <inertial>
      <origin rpy="0 0 0" xyz="-0.0016559 2.498E-05 -1.1185E-05"/>
      <mass value="1.1363"/>
      <inertia ixx="0.0049366" ixy="-9.2744E-07" ixz="2.0492E-07" iyy="0.002578" iyz="9.052E-08" izz="0.0025791"/>
    </inertial>
    <visual>
      <origin rpy="0 0 0" xyz="0 0 0"/>
      <geometry>
        <mesh filename="package://ranger_mini/meshes/ffl_wheel_link.STL"/>
      </geometry>
      <material name="">
        <color rgba="0.79216 0.81961 0.93333 1"/>
      </material>
    </visual>
    <collision>
      <origin rpy="0 0 0" xyz="0 0 0"/>
      <geometry>
        <mesh filename="package://ranger_mini/meshes/ffl_wheel_link.STL"/>
      </geometry>
    </collision>
  </link>
  <joint name="ffl_wheel_joint" type="continuous">
    <origin rpy="0 0 0" xyz="-0.0012329 0.00099823 0.179"/>
    <parent link="front_left_steering_link"/>
    <child link="ffl_wheel_link"/>
    <axis xyz="1 0 0"/>
    <limit effort="1.5" velocity="20"/>
  </joint>
  <link name="front_right_steering_link">
    <inertial>
      <origin rpy="0 0 0" xyz="0.0078149 5.813E-06 0.060941"/>
      <mass value="0.30422"/>
      <inertia ixx="0.00022406" ixy="-6.6817E-09" ixz="7.4999E-08" iyy="0.00021285" iyz="-1.9079E-08" izz="0.00027948"/>
    </inertial>
    <visual>
      <origin rpy="0 0 0" xyz="0 0 0"/>
      <geometry>
        <mesh filename="package://ranger_mini/meshes/front_right_steering_link.STL"/>
      </geometry>
      <material name="">
        <color rgba="0.79216 0.81961 0.93333 1"/>
      </material>
    </visual>
    <collision>
      <origin rpy="0 0 0" xyz="0 0 0"/>
      <geometry>
        <mesh filename="package://ranger_mini/meshes/front_right_steering_link.STL"/>
      </geometry>
    </collision>
  </link>
  <joint name="front_right_steering_joint" type="revolute">
    <origin rpy="3.1416 0 1.5708" xyz="0.26366 -0.18 0.0557"/>
    <parent link="base_link"/>
    <child link="front_right_steering_link"/>
    <axis xyz="0 0 1"/>
    <limit effort="5" lower="-2.1" upper="2.1" velocity="6.28"/>
  </joint>
  <link name="ffr_wheel_link">
    <inertial>
      <origin rpy="0 0 0" xyz="0.0016472 -1.6563E-05 2.7857E-05"/>
      <mass value="1.1364"/>
      <inertia ixx="0.0049371" ixy="-9.2722E-07" ixz="-1.9886E-07" iyy="0.0025793" iyz="-6.7378E-08" izz="0.0025805"/>
    </inertial>
    <visual>
      <origin rpy="0 0 0" xyz="0 0 0"/>
      <geometry>
        <mesh filename="package://ranger_mini/meshes/ffr_wheel_link.STL"/>
      </geometry>
      <material name="">
        <color rgba="0.79216 0.81961 0.93333 1"/>
      </material>
    </visual>
    <collision>
      <origin rpy="0 0 0" xyz="0 0 0"/>
      <geometry>
        <mesh filename="package://ranger_mini/meshes/ffr_wheel_link.STL"/>
      </geometry>
    </collision>
  </link>
  <joint name="ffr_wheel_joint" type="continuous">
    <origin rpy="0 0 0" xyz="0.0012238 0 0.179"/>
    <parent link="front_right_steering_link"/>
    <child link="ffr_wheel_link"/>
    <axis xyz="1 0 0"/>
    <limit effort="1.5" velocity="20"/>
  </joint>
  <link name="rear_left_steering_link">
    <inertial>
      <origin rpy="0 0 0" xyz="-0.0079979 9.6737E-06 0.062261"/>
      <mass value="0.2968"/>
      <inertia ixx="0.00021788" ixy="-5.0547E-08" ixz="-7.6105E-09" iyy="0.00020665" iyz="1.9139E-08" izz="0.00026712"/>
    </inertial>
    <visual>
      <origin rpy="0 0 0" xyz="0 0 0"/>
      <geometry>
        <mesh filename="package://ranger_mini/meshes/rear_left_steering_link.STL"/>
      </geometry>
      <material name="">
        <color rgba="0.79216 0.81961 0.93333 1"/>
      </material>
    </visual>
    <collision>
      <origin rpy="0 0 0" xyz="0 0 0"/>
      <geometry>
        <mesh filename="package://ranger_mini/meshes/rear_left_steering_link.STL"/>
      </geometry>
    </collision>
  </link>
  <joint name="rear_left_steering_joint" type="revolute">
    <origin rpy="3.1416 0 1.5708" xyz="-0.094631 0.18001 0.0557"/>
    <parent link="base_link"/>
    <child link="rear_left_steering_link"/>
    <axis xyz="0 0 1"/>
    <limit effort="5" lower="-2.1" upper="2.1" velocity="6.28"/>
  </joint>
  <link name="rfl_wheel_link">
    <inertial>
      <origin rpy="0 0 0" xyz="-0.0016588 2.035E-05 8.7225E-06"/>
      <mass value="1.1361"/>
      <inertia ixx="0.0049373" ixy="-9.2167E-07" ixz="1.9763E-07" iyy="0.0025788" iyz="3.731E-07" izz="0.002579"/>
    </inertial>
    <visual>
      <origin rpy="0 0 0" xyz="0 0 0"/>
      <geometry>
        <mesh filename="package://ranger_mini/meshes/rfl_wheel_link.STL"/>
      </geometry>
      <material name="">
        <color rgba="0.79216 0.81961 0.93333 1"/>
      </material>
    </visual>
    <collision>
      <origin rpy="0 0 0" xyz="0 0 0"/>
      <geometry>
        <mesh filename="package://ranger_mini/meshes/rfl_wheel_link.STL"/>
      </geometry>
    </collision>
  </link>
  <joint name="rfl_wheel_joint" type="continuous">
    <origin rpy="0 0 0" xyz="-0.0012297 0 0.179"/>
    <parent link="rear_left_steering_link"/>
    <child link="rfl_wheel_link"/>
    <axis xyz="1 0 0"/>
    <limit effort="1.5" velocity="20"/>
  </joint>
  <link name="rear_right_steering_link">
    <inertial>
      <origin rpy="0 0 0" xyz="0.0077929 0.00010875 0.060976"/>
      <mass value="0.30421"/>
      <inertia ixx="0.00022406" ixy="1.5622E-07" ixz="7.4851E-09" iyy="0.00021285" iyz="1.9677E-08" izz="0.00027948"/>
    </inertial>
    <visual>
      <origin rpy="0 0 0" xyz="0 0 0"/>
      <geometry>
        <mesh filename="package://ranger_mini/meshes/rear_right_steering_link.STL"/>
      </geometry>
      <material name="">
        <color rgba="0.79216 0.81961 0.93333 1"/>
      </material>
    </visual>
    <collision>
      <origin rpy="0 0 0" xyz="0 0 0"/>
      <geometry>
        <mesh filename="package://ranger_mini/meshes/rear_right_steering_link.STL"/>
      </geometry>
    </collision>
  </link>
  <joint name="rear_right_steering_joint" type="revolute">
    <origin rpy="3.1416 0 1.5708" xyz="-0.09463 -0.17999 0.0557"/>
    <parent link="base_link"/>
    <child link="rear_right_steering_link"/>
    <axis xyz="0 0 1"/>
    <limit effort="5" lower="-2.1" upper="2.1" velocity="6.28"/>
  </joint>
  <link name="rfr_wheel_link">
    <inertial>
      <origin rpy="0 0 0" xyz="0.0016568 3.1298E-06 9.7006E-06"/>
      <mass value="1.1361"/>
      <inertia ixx="0.0049373" ixy="3.3232E-05" ixz="-1.942E-07" iyy="0.0025802" iyz="-1.2121E-07" izz="0.0025792"/>
    </inertial>
    <visual>
      <origin rpy="0 0 0" xyz="0 0 0"/>
      <geometry>
        <mesh filename="package://ranger_mini/meshes/rfr_wheel_link.STL"/>
      </geometry>
      <material name="">
        <color rgba="0.79216 0.81961 0.93333 1"/>
      </material>
    </visual>
    <collision>
      <origin rpy="0 0 0" xyz="0 0 0"/>
      <geometry>
        <mesh filename="package://ranger_mini/meshes/rfr_wheel_link.STL"/>
      </geometry>
    </collision>
  </link>
  <joint name="rfr_wheel_joint" type="continuous">
    <origin rpy="0 0 0" xyz="0.0012149 0 0.179"/>
    <parent link="rear_right_steering_link"/>
    <child link="rfr_wheel_link"/>
    <axis xyz="1 0 0"/>
    <limit effort="1.5" velocity="20"/>
  </joint>
  <transmission name="front_left_steering_trans">
    <type>transmission_interface/SimpleTransmission</type>
    <joint name="front_left_steering_joint">
      <hardwareInterface>hardware_interface/PositionJointInterface</hardwareInterface>
    </joint>
    <actuator name="front_left_steering_motor">
      <hardwareInterface>hardware_interface/PositionJointInterface</hardwareInterface>
      <mechanicalReduction>30</mechanicalReduction>
    </actuator>
  </transmission>
  <transmission name="front_right_steering_trans">
    <type>transmission_interface/SimpleTransmission</type>
    <joint name="front_right_steering_joint">
      <hardwareInterface>hardware_interface/PositionJointInterface</hardwareInterface>
    </joint>
    <actuator name="front_right_steering_motor">
      <hardwareInterface>hardware_interface/PositionJointInterface</hardwareInterface>
      <mechanicalReduction>30</mechanicalReduction>
    </actuator>
  </transmission>
  <transmission name="rear_left_steering_trans">
    <type>transmission_interface/SimpleTransmission</type>
    <joint name="rear_left_steering_joint">
      <hardwareInterface>hardware_interface/PositionJointInterface</hardwareInterface>
    </joint>
    <actuator name="rear_left_steering_motor">
      <hardwareInterface>hardware_interface/PositionJointInterface</hardwareInterface>
      <mechanicalReduction>30</mechanicalReduction>
    </actuator>
  </transmission>
  <transmission name="rear_right_steering_trans">
    <type>transmission_interface/SimpleTransmission</type>
    <joint name="rear_right_steering_joint">
      <hardwareInterface>hardware_interface/PositionJointInterface</hardwareInterface>
    </joint>
    <actuator name="rear_right_steering_motor">
      <hardwareInterface>hardware_interface/PositionJointInterface</hardwareInterface>
      <mechanicalReduction>30</mechanicalReduction>
    </actuator>
  </transmission>
  <transmission name="ffl_wheel_trans">
    <type>transmission_interface/SimpleTransmission</type>
    <joint name="ffl_wheel_joint">
      <hardwareInterface>hardware_interface/VelocityJointInterface</hardwareInterface>
    </joint>
    <actuator name="ffl_wheel_motor">
      <hardwareInterface>hardware_interface/VelocityJointInterface</hardwareInterface>
      <mechanicalReduction>1</mechanicalReduction>
    </actuator>
  </transmission>
  <transmission name="ffr_wheel_trans">
    <type>transmission_interface/SimpleTransmission</type>
    <joint name="ffr_wheel_joint">
      <hardwareInterface>hardware_interface/VelocityJointInterface</hardwareInterface>
    </joint>
    <actuator name="ffr_wheel_motor">
      <hardwareInterface>hardware_interface/VelocityJointInterface</hardwareInterface>
      <mechanicalReduction>1</mechanicalReduction>
    </actuator>
  </transmission>
  <transmission name="rfl_wheel_trans">
    <type>transmission_interface/SimpleTransmission</type>
    <joint name="rfl_wheel_joint">
      <hardwareInterface>hardware_interface/VelocityJointInterface</hardwareInterface>
    </joint>
    <actuator name="rfl_wheel_motor">
      <hardwareInterface>hardware_interface/VelocityJointInterface</hardwareInterface>
      <mechanicalReduction>1</mechanicalReduction>
    </actuator>
  </transmission>
  <transmission name="rfr_wheel_trans">
    <type>transmission_interface/SimpleTransmission</type>
    <joint name="rfr_wheel_joint">
      <hardwareInterface>hardware_interface/VelocityJointInterface</hardwareInterface>
    </joint>
    <actuator name="rfr_wheel_motor">
      <hardwareInterface>hardware_interface/VelocityJointInterface</hardwareInterface>
      <mechanicalReduction>1</mechanicalReduction>
    </actuator>
  </transmission>
  <gazebo>
    <plugin filename="libgazebo_ros_control.so" name="gazebo_ros_control">
    </plugin>
  </gazebo>
  <!-- <gazebo>
        <plugin name="gazebo_ros_control" filename="libgazebo_ros_control.so">
            <robotNamespace>/z1_gazebo</robotNamespace>
            <robotSimType>gazebo_ros_control/DefaultRobotHWSim</robotSimType>
        </plugin>
    </gazebo> -->
  <gazebo reference="link04">
    <self_collide>true</self_collide>
  </gazebo>
  <gazebo reference="link05">
    <self_collide>true</self_collide>
  </gazebo>
  <gazebo reference="link06">
    <self_collide>true</self_collide>
  </gazebo>
  <!-- <link name="world"/> -->
  <!-- <joint name="base_static_joint" type="fixed">
        <origin rpy="0 0 0" xyz="0 0 0"/>
        <parent link="world"/>
        <child link="link00"/>
    </joint> -->
  <link name="link00">
    <visual>
      <origin rpy="0 0 0" xyz="0 0 0"/>
      <geometry>
        <mesh filename="package://z1_description/meshes/visual/z1_Link00.dae" scale="1 1 1"/>
      </geometry>
    </visual>
    <collision>
      <geometry>
        <cylinder length="0.051" radius="0.0325"/>
      </geometry>
      <origin rpy="0 0 0" xyz="0 0 0.0255"/>
    </collision>
    <inertial>
      <origin rpy="0 0 0" xyz="-0.00334984 -0.00013615 0.02495843"/>
      <mass value="0.47247481"/>
      <inertia ixx="0.00037937" ixy="-3.5e-07" ixz="-1.037e-05" iyy="0.00041521" iyz="-9.9e-07" izz="0.00053066"/>
    </inertial>
  </link>
  <joint name="joint1" type="revolute">
    <origin rpy="0 0 0" xyz="0 0 0.0585"/>
    <parent link="link00"/>
    <child link="link01"/>
    <axis xyz="0 0 1"/>
    <dynamics damping="1.0" friction="1.0"/>
    <limit effort="30.0" lower="-2.6179938779914944" upper="2.6179938779914944" velocity="3.1415"/>
  </joint>
  <link name="link01">
    <visual>
      <origin rpy="0 0 0" xyz="0 0 0"/>
      <geometry>
        <mesh filename="package://z1_description/meshes/visual/z1_Link01.dae" scale="1 1 1"/>
      </geometry>
    </visual>
    <inertial>
      <origin rpy="0 0 0" xyz="2.47e-06 -0.00025198 0.02317169"/>
      <mass value="0.67332551"/>
      <inertia ixx="0.00128328" ixy="-6e-08" ixz="-4e-07" iyy="0.00071931" iyz="5e-07" izz="0.00083936"/>
    </inertial>
  </link>
  <joint name="joint2" type="revolute">
    <origin rpy="0 0 0" xyz="0 0 0.045"/>
    <parent link="link01"/>
    <child link="link02"/>
    <axis xyz="0 1 0"/>
    <dynamics damping="2.0" friction="2.0"/>
    <limit effort="60.0" lower="0.0" upper="2.9670597283903604" velocity="3.1415"/>
  </joint>
  <link name="link02">
    <visual>
      <origin rpy="0 0 0" xyz="0 0 0"/>
      <geometry>
        <mesh filename="package://z1_description/meshes/visual/z1_Link02.dae" scale="1 1 1"/>
      </geometry>
    </visual>
    <collision>
      <geometry>
        <cylinder length="0.102" radius="0.0325"/>
      </geometry>
      <origin rpy="1.5707963267948966 0 0" xyz="0 0 0"/>
    </collision>
    <collision>
      <geometry>
        <cylinder length="0.235" radius="0.0225"/>
      </geometry>
      <origin rpy="0 1.5707963267948966 0" xyz="-0.16249999999999998 0 0"/>
    </collision>
    <collision>
      <geometry>
        <cylinder length="0.051" radius="0.0325"/>
      </geometry>
      <origin rpy="1.5707963267948966 0 0" xyz="-0.35 0 0"/>
    </collision>
    <inertial>
      <origin rpy="0 0 0" xyz="-0.11012601 0.00240029 0.00158266"/>
      <mass value="1.19132258"/>
      <inertia ixx="0.00102138" ixy="0.00062358" ixz="5.13e-06" iyy="0.02429457" iyz="-2.1e-06" izz="0.02466114"/>
    </inertial>
  </link>
  <joint name="joint3" type="revolute">
    <origin rpy="0 0 0" xyz="-0.35 0 0"/>
    <parent link="link02"/>
    <child link="link03"/>
    <axis xyz="0 1 0"/>
    <dynamics damping="1.0" friction="1.0"/>
    <limit effort="30.0" lower="-2.8797932657906435" upper="0.0" velocity="3.1415"/>
  </joint>
  <link name="link03">
    <visual>
      <origin rpy="0 0 0" xyz="0 0 0"/>
      <geometry>
        <mesh filename="package://z1_description/meshes/visual/z1_Link03.dae" scale="1 1 1"/>
      </geometry>
    </visual>
    <collision>
      <geometry>
        <cylinder length="0.116" radius="0.02"/>
      </geometry>
      <origin rpy="0 1.5707963267948966 0" xyz="0.128 0 0.055"/>
    </collision>
    <collision>
      <geometry>
        <cylinder length="0.059" radius="0.0325"/>
      </geometry>
      <origin rpy="0 1.5707963267948966 1.5707963267948966" xyz="0.2205 0 0.055"/>
    </collision>
    <inertial>
      <origin rpy="0 0 0" xyz="0.10609208 -0.00541815 0.03476383"/>
      <mass value="0.83940874"/>
      <inertia ixx="0.00108061" ixy="-8.669e-05" ixz="-0.00208102" iyy="0.00954238" iyz="-1.332e-05" izz="0.00886621"/>
    </inertial>
  </link>
  <joint name="joint4" type="revolute">
    <origin rpy="0 0 0" xyz="0.218 0 0.057"/>
    <parent link="link03"/>
    <child link="link04"/>
    <axis xyz="0 1 0"/>
    <dynamics damping="1.0" friction="1.0"/>
    <limit effort="30.0" lower="-1.5184364492350666" upper="1.5184364492350666" velocity="3.1415"/>
  </joint>
  <link name="link04">
    <visual>
      <origin rpy="0 0 0" xyz="0 0 0"/>
      <geometry>
        <mesh filename="package://z1_description/meshes/visual/z1_Link04.dae" scale="1 1 1"/>
      </geometry>
    </visual>
    <collision>
      <geometry>
        <cylinder length="0.067" radius="0.0325"/>
      </geometry>
      <origin rpy="0 0 0" xyz="0.072 0 0"/>
    </collision>
    <inertial>
      <origin rpy="0 0 0" xyz="0.04366681 0.00364738 -0.00170192"/>
      <mass value="0.56404563"/>
      <inertia ixx="0.00031576" ixy="8.13e-05" ixz="4.091e-05" iyy="0.00092996" iyz="-5.96e-06" izz="0.00097912"/>
    </inertial>
  </link>
  <joint name="joint5" type="revolute">
    <origin rpy="0 0 0" xyz="0.07 0.0 0.0"/>
    <parent link="link04"/>
    <child link="link05"/>
    <axis xyz="0 0 1"/>
    <dynamics damping="1.0" friction="1.0"/>
    <limit effort="30.0" lower="-1.3439035240356338" upper="1.3439035240356338" velocity="3.1415"/>
  </joint>
  <link name="link05">
    <visual>
      <origin rpy="0 0 0" xyz="0 0 0"/>
      <geometry>
        <mesh filename="package://z1_description/meshes/visual/z1_Link05.dae" scale="1 1 1"/>
      </geometry>
    </visual>
    <inertial>
      <origin rpy="0 0 0" xyz="0.03121533 0.0 0.00646316"/>
      <mass value="0.38938492"/>
      <inertia ixx="0.00017605" ixy="4e-07" ixz="5.689e-05" iyy="0.00055896" iyz="-1.3e-07" izz="0.0005386"/>
    </inertial>
  </link>
  <joint name="joint6" type="revolute">
    <origin rpy="0 0 0" xyz="0.0492 0.0 0.0"/>
    <parent link="link05"/>
    <child link="link06"/>
    <axis xyz="1 0 0"/>
    <dynamics damping="1.0" friction="1.0"/>
    <limit effort="30.0" lower="-2.792526803190927" upper="2.792526803190927" velocity="3.1415"/>
  </joint>
  <link name="link06">
    <visual>
      <origin rpy="0 0 0" xyz="0 0 0"/>
      <geometry>
        <mesh filename="package://z1_description/meshes/visual/z1_Link06.dae" scale="1 1 1"/>
      </geometry>
    </visual>
    <collision>
      <geometry>
        <cylinder length="0.051" radius="0.0325"/>
      </geometry>
      <origin rpy="0 1.5707963267948966 0" xyz="0.0255 0 0"/>
    </collision>
    <inertial>
      <origin rpy="0 0 0" xyz="0.0241569 -0.00017355 -0.00143876"/>
      <mass value="0.28875807"/>
      <inertia ixx="0.00018328" ixy="1.22e-06" ixz="5.4e-07" iyy="0.0001475" iyz="8e-08" izz="0.0001468"/>
    </inertial>
  </link>
  <joint name="gripperStator" type="fixed">
    <origin rpy="0 0 0" xyz="0.051 0.0 0.0"/>
    <parent link="link06"/>
    <child link="gripperStator"/>
  </joint>
  <link name="gripperStator">
    <visual>
      <geometry>
        <mesh filename="package://z1_description/meshes/visual/z1_GripperStator.dae" scale="1 1 1"/>
      </geometry>
    </visual>
    <collision>
      <geometry>
        <mesh filename="package://z1_description/meshes/collision/z1_GripperStator.STL" scale="1 1 1"/>
      </geometry>
    </collision>
    <inertial>
      <origin rpy="0 0 0" xyz="0.04764427 -0.00035819 -0.00249162"/>
      <mass value="0.52603655"/>
      <inertia ixx="0.00038683" ixy="-3.59e-06" ixz="7.662e-05" iyy="0.00068614" iyz="2.09e-06" izz="0.00066293"/>
    </inertial>
  </link>
  <joint name="jointGripper" type="revolute">
    <origin rpy="0 0 0" xyz="0.049 0.0 0"/>
    <parent link="gripperStator"/>
    <child link="gripperMover"/>
    <axis xyz="0 1 0"/>
    <dynamics damping="1.0" friction="1.0"/>
    <limit effort="30.0" lower="-1.5707963267948966" upper="0.0" velocity="3.1415"/>
  </joint>
  <link name="gripperMover">
    <visual>
      <geometry>
        <mesh filename="package://z1_description/meshes/visual/z1_GripperMover.dae" scale="1 1 1"/>
      </geometry>
    </visual>
    <collision>
      <geometry>
        <mesh filename="package://z1_description/meshes/collision/z1_GripperMover.STL" scale="1 1 1"/>
      </geometry>
    </collision>
    <inertial>
      <origin rpy="0 0 0" xyz="0.01320633 0.00476708 0.00380534"/>
      <mass value="0.27621302"/>
      <inertia ixx="0.00017716" ixy="1.683e-05" ixz="-1.786e-05" iyy="0.00026787" iyz="2.62e-06" izz="0.00035728"/>
    </inertial>
  </link>
  <transmission name="JointTransGripper">
    <type>transmission_interface/SimpleTransmission</type>
    <joint name="jointGripper">
      <hardwareInterface>hardware_interface/EffortJointInterface</hardwareInterface>
    </joint>
    <actuator name="ActuatorGripper">
      <hardwareInterface>hardware_interface/EffortJointInterface</hardwareInterface>
      <mechanicalReduction>1</mechanicalReduction>
    </actuator>
  </transmission>
  <gazebo reference="gripperStator">
    <self_collide>true</self_collide>
  </gazebo>
  <gazebo reference="gripperMover">
    <self_collide>true</self_collide>
  </gazebo>
  <transmission name="JointTrans1">
    <type>transmission_interface/SimpleTransmission</type>
    <joint name="joint1">
      <hardwareInterface>hardware_interface/EffortJointInterface</hardwareInterface>
    </joint>
    <actuator name="Actuator1">
      <hardwareInterface>hardware_interface/EffortJointInterface</hardwareInterface>
      <mechanicalReduction>1</mechanicalReduction>
    </actuator>
  </transmission>
  <transmission name="JointTrans2">
    <type>transmission_interface/SimpleTransmission</type>
    <joint name="joint2">
      <hardwareInterface>hardware_interface/EffortJointInterface</hardwareInterface>
    </joint>
    <actuator name="Actuator2">
      <hardwareInterface>hardware_interface/EffortJointInterface</hardwareInterface>
      <mechanicalReduction>1</mechanicalReduction>
    </actuator>
  </transmission>
  <transmission name="JointTrans3">
    <type>transmission_interface/SimpleTransmission</type>
    <joint name="joint3">
      <hardwareInterface>hardware_interface/EffortJointInterface</hardwareInterface>
    </joint>
    <actuator name="Actuator3">
      <hardwareInterface>hardware_interface/EffortJointInterface</hardwareInterface>
      <mechanicalReduction>1</mechanicalReduction>
    </actuator>
  </transmission>
  <transmission name="JointTrans4">
    <type>transmission_interface/SimpleTransmission</type>
    <joint name="joint4">
      <hardwareInterface>hardware_interface/EffortJointInterface</hardwareInterface>
    </joint>
    <actuator name="Actuator4">
      <hardwareInterface>hardware_interface/EffortJointInterface</hardwareInterface>
      <mechanicalReduction>1</mechanicalReduction>
    </actuator>
  </transmission>
  <transmission name="JointTrans5">
    <type>transmission_interface/SimpleTransmission</type>
    <joint name="joint5">
      <hardwareInterface>hardware_interface/EffortJointInterface</hardwareInterface>
    </joint>
    <actuator name="Actuator5">
      <hardwareInterface>hardware_interface/EffortJointInterface</hardwareInterface>
      <mechanicalReduction>1</mechanicalReduction>
    </actuator>
  </transmission>
  <transmission name="JointTrans6">
    <type>transmission_interface/SimpleTransmission</type>
    <joint name="joint6">
      <hardwareInterface>hardware_interface/EffortJointInterface</hardwareInterface>
    </joint>
    <actuator name="Actuator6">
      <hardwareInterface>hardware_interface/EffortJointInterface</hardwareInterface>
      <mechanicalReduction>1</mechanicalReduction>
    </actuator>
  </transmission>
  <joint name="arm2base_link" type="fixed">
    <parent link="base_link"/>
    <child link="link00"/>
    <origin xyz="0.1 0.0 0.2"/>
  </joint>
  <!-- <gazebo>
    <plugin name="gazebo_ros_control" filename="libgazebo_ros_control.so">
    </plugin>
  </gazebo> -->
</robot>

